2025-03-05 15:34:59,567 INFO    Thread-493 (_run_job):33248 [wandb_setup.py:_flush():67] Current SDK version is 0.19.7
2025-03-05 15:34:59,567 INFO    Thread-493 (_run_job):33248 [wandb_setup.py:_flush():67] Configure stats pid to 33248
2025-03-05 15:34:59,567 INFO    Thread-493 (_run_job):33248 [wandb_setup.py:_flush():67] Loading settings from C:\Users\Siddhant\.config\wandb\settings
2025-03-05 15:34:59,567 INFO    Thread-493 (_run_job):33248 [wandb_setup.py:_flush():67] Loading settings from C:\da24m021_da6401_assignment1\wandb\settings
2025-03-05 15:34:59,567 INFO    Thread-493 (_run_job):33248 [wandb_setup.py:_flush():67] Loading settings from environment variables
2025-03-05 15:34:59,567 INFO    Thread-493 (_run_job):33248 [wandb_init.py:setup_run_log_directory():647] Logging user logs to C:\da24m021_da6401_assignment1\wandb\run-20250305_153459-ck3bqv19\logs\debug.log
2025-03-05 15:34:59,569 INFO    Thread-493 (_run_job):33248 [wandb_init.py:setup_run_log_directory():648] Logging internal logs to C:\da24m021_da6401_assignment1\wandb\run-20250305_153459-ck3bqv19\logs\debug-internal.log
2025-03-05 15:34:59,570 INFO    Thread-493 (_run_job):33248 [wandb_init.py:init():761] calling init triggers
2025-03-05 15:34:59,570 INFO    Thread-493 (_run_job):33248 [wandb_init.py:init():766] wandb.init called with sweep_config: {'activation': 'tanh', 'batch_size': 32, 'dataset': 'fashion_mnist', 'dropout': 0, 'epochs': 10, 'hidden_size': 32, 'learning_rate': 0.0001, 'loss': 'cross_entropy', 'num_layers': 3, 'optimizer': 'momentum', 'weight_init': 'random'}
config: {'_wandb': {}}
2025-03-05 15:34:59,570 INFO    Thread-493 (_run_job):33248 [wandb_init.py:init():784] starting backend
2025-03-05 15:34:59,570 INFO    Thread-493 (_run_job):33248 [wandb_init.py:init():788] sending inform_init request
2025-03-05 15:34:59,582 INFO    Thread-493 (_run_job):33248 [backend.py:_multiprocessing_setup():97] multiprocessing start_methods=spawn, using: spawn
2025-03-05 15:34:59,583 INFO    Thread-493 (_run_job):33248 [wandb_init.py:init():803] backend started and connected
2025-03-05 15:34:59,586 INFO    Thread-493 (_run_job):33248 [wandb_run.py:_config_callback():1261] config_cb None None {'activation': 'tanh', 'batch_size': 32, 'dataset': 'fashion_mnist', 'dropout': 0, 'epochs': 10, 'hidden_size': 32, 'learning_rate': 0.0001, 'loss': 'cross_entropy', 'num_layers': 3, 'optimizer': 'momentum', 'weight_init': 'random'}
2025-03-05 15:34:59,587 INFO    Thread-493 (_run_job):33248 [wandb_init.py:init():896] updated telemetry
2025-03-05 15:34:59,684 INFO    Thread-493 (_run_job):33248 [wandb_init.py:init():920] communicating run to backend with 90.0 second timeout
2025-03-05 15:35:00,629 INFO    Thread-493 (_run_job):33248 [wandb_init.py:init():995] starting run threads in backend
2025-03-05 15:35:01,082 INFO    Thread-493 (_run_job):33248 [wandb_run.py:_console_start():2377] atexit reg
2025-03-05 15:35:01,083 INFO    Thread-493 (_run_job):33248 [wandb_run.py:_redirect():2227] redirect: wrap_raw
2025-03-05 15:35:01,083 INFO    Thread-493 (_run_job):33248 [wandb_run.py:_redirect():2292] Wrapping output streams.
2025-03-05 15:35:01,083 INFO    Thread-493 (_run_job):33248 [wandb_run.py:_redirect():2317] Redirects installed.
2025-03-05 15:35:01,084 INFO    Thread-493 (_run_job):33248 [wandb_init.py:init():1037] run started, returning control to user process
2025-03-05 15:35:01,084 INFO    Thread-493 (_run_job):33248 [wandb_run.py:_config_callback():1261] config_cb None None {'NAME': 'SIDDHANT BARANWAL', 'ROLL NO.': 'DA24M021'}
2025-03-05 15:35:52,307 INFO    Thread-7 (_heartbeat):33248 [retry.py:__call__():175] Retry attempt failed:
Traceback (most recent call last):
  File "C:\Users\Siddhant\AppData\Local\Programs\Python\Python312\Lib\site-packages\urllib3\connection.py", line 199, in _new_conn
    sock = connection.create_connection(
           ^^^^^^^^^^^^^^^^^^^^^^^^^^^^^
  File "C:\Users\Siddhant\AppData\Local\Programs\Python\Python312\Lib\site-packages\urllib3\util\connection.py", line 60, in create_connection
    for res in socket.getaddrinfo(host, port, family, socket.SOCK_STREAM):
               ^^^^^^^^^^^^^^^^^^^^^^^^^^^^^^^^^^^^^^^^^^^^^^^^^^^^^^^^^^
  File "C:\Users\Siddhant\AppData\Local\Programs\Python\Python312\Lib\socket.py", line 976, in getaddrinfo
    for res in _socket.getaddrinfo(host, port, family, type, proto, flags):
               ^^^^^^^^^^^^^^^^^^^^^^^^^^^^^^^^^^^^^^^^^^^^^^^^^^^^^^^^^^^
socket.gaierror: [Errno 11001] getaddrinfo failed

The above exception was the direct cause of the following exception:

Traceback (most recent call last):
  File "C:\Users\Siddhant\AppData\Local\Programs\Python\Python312\Lib\site-packages\urllib3\connectionpool.py", line 789, in urlopen
    response = self._make_request(
               ^^^^^^^^^^^^^^^^^^^
  File "C:\Users\Siddhant\AppData\Local\Programs\Python\Python312\Lib\site-packages\urllib3\connectionpool.py", line 490, in _make_request
    raise new_e
  File "C:\Users\Siddhant\AppData\Local\Programs\Python\Python312\Lib\site-packages\urllib3\connectionpool.py", line 466, in _make_request
    self._validate_conn(conn)
  File "C:\Users\Siddhant\AppData\Local\Programs\Python\Python312\Lib\site-packages\urllib3\connectionpool.py", line 1095, in _validate_conn
    conn.connect()
  File "C:\Users\Siddhant\AppData\Local\Programs\Python\Python312\Lib\site-packages\urllib3\connection.py", line 693, in connect
    self.sock = sock = self._new_conn()
                       ^^^^^^^^^^^^^^^^
  File "C:\Users\Siddhant\AppData\Local\Programs\Python\Python312\Lib\site-packages\urllib3\connection.py", line 206, in _new_conn
    raise NameResolutionError(self.host, self, e) from e
urllib3.exceptions.NameResolutionError: <urllib3.connection.HTTPSConnection object at 0x000001BF1C24E000>: Failed to resolve 'api.wandb.ai' ([Errno 11001] getaddrinfo failed)

The above exception was the direct cause of the following exception:

Traceback (most recent call last):
  File "C:\Users\Siddhant\AppData\Local\Programs\Python\Python312\Lib\site-packages\requests\adapters.py", line 667, in send
    resp = conn.urlopen(
           ^^^^^^^^^^^^^
  File "C:\Users\Siddhant\AppData\Local\Programs\Python\Python312\Lib\site-packages\urllib3\connectionpool.py", line 843, in urlopen
    retries = retries.increment(
              ^^^^^^^^^^^^^^^^^^
  File "C:\Users\Siddhant\AppData\Local\Programs\Python\Python312\Lib\site-packages\urllib3\util\retry.py", line 519, in increment
    raise MaxRetryError(_pool, url, reason) from reason  # type: ignore[arg-type]
    ^^^^^^^^^^^^^^^^^^^^^^^^^^^^^^^^^^^^^^^^^^^^^^^^^^^
urllib3.exceptions.MaxRetryError: HTTPSConnectionPool(host='api.wandb.ai', port=443): Max retries exceeded with url: /graphql (Caused by NameResolutionError("<urllib3.connection.HTTPSConnection object at 0x000001BF1C24E000>: Failed to resolve 'api.wandb.ai' ([Errno 11001] getaddrinfo failed)"))

During handling of the above exception, another exception occurred:

Traceback (most recent call last):
  File "C:\Users\Siddhant\AppData\Local\Programs\Python\Python312\Lib\site-packages\wandb\sdk\lib\retry.py", line 134, in __call__
    result = self._call_fn(*args, **kwargs)
             ^^^^^^^^^^^^^^^^^^^^^^^^^^^^^^
  File "C:\Users\Siddhant\AppData\Local\Programs\Python\Python312\Lib\site-packages\wandb\sdk\internal\internal_api.py", line 398, in execute
    return self.client.execute(*args, **kwargs)  # type: ignore
           ^^^^^^^^^^^^^^^^^^^^^^^^^^^^^^^^^^^^
  File "C:\Users\Siddhant\AppData\Local\Programs\Python\Python312\Lib\site-packages\wandb\vendor\gql-0.2.0\wandb_gql\client.py", line 52, in execute
    result = self._get_result(document, *args, **kwargs)
             ^^^^^^^^^^^^^^^^^^^^^^^^^^^^^^^^^^^^^^^^^^^
  File "C:\Users\Siddhant\AppData\Local\Programs\Python\Python312\Lib\site-packages\wandb\vendor\gql-0.2.0\wandb_gql\client.py", line 60, in _get_result
    return self.transport.execute(document, *args, **kwargs)
           ^^^^^^^^^^^^^^^^^^^^^^^^^^^^^^^^^^^^^^^^^^^^^^^^^
  File "C:\Users\Siddhant\AppData\Local\Programs\Python\Python312\Lib\site-packages\wandb\sdk\lib\gql_request.py", line 58, in execute
    request = self.session.post(self.url, **post_args)
              ^^^^^^^^^^^^^^^^^^^^^^^^^^^^^^^^^^^^^^^^
  File "C:\Users\Siddhant\AppData\Local\Programs\Python\Python312\Lib\site-packages\requests\sessions.py", line 637, in post
    return self.request("POST", url, data=data, json=json, **kwargs)
           ^^^^^^^^^^^^^^^^^^^^^^^^^^^^^^^^^^^^^^^^^^^^^^^^^^^^^^^^^
  File "C:\Users\Siddhant\AppData\Local\Programs\Python\Python312\Lib\site-packages\requests\sessions.py", line 589, in request
    resp = self.send(prep, **send_kwargs)
           ^^^^^^^^^^^^^^^^^^^^^^^^^^^^^^
  File "C:\Users\Siddhant\AppData\Local\Programs\Python\Python312\Lib\site-packages\requests\sessions.py", line 703, in send
    r = adapter.send(request, **kwargs)
        ^^^^^^^^^^^^^^^^^^^^^^^^^^^^^^^
  File "C:\Users\Siddhant\AppData\Local\Programs\Python\Python312\Lib\site-packages\requests\adapters.py", line 700, in send
    raise ConnectionError(e, request=request)
requests.exceptions.ConnectionError: HTTPSConnectionPool(host='api.wandb.ai', port=443): Max retries exceeded with url: /graphql (Caused by NameResolutionError("<urllib3.connection.HTTPSConnection object at 0x000001BF1C24E000>: Failed to resolve 'api.wandb.ai' ([Errno 11001] getaddrinfo failed)"))
2025-03-05 15:35:55,451 INFO    Thread-493 (_run_job):33248 [wandb_run.py:_finish():2112] finishing run da24m021-indian-institute-of-technology-madras/da24m021_da6401_assignment1/ck3bqv19
2025-03-05 15:35:55,452 INFO    Thread-493 (_run_job):33248 [wandb_run.py:_atexit_cleanup():2342] got exitcode: 0
2025-03-05 15:35:55,452 INFO    Thread-493 (_run_job):33248 [wandb_run.py:_restore():2324] restore
2025-03-05 15:35:55,452 INFO    Thread-493 (_run_job):33248 [wandb_run.py:_restore():2330] restore done
2025-03-05 15:36:13,683 INFO    MsgRouterThr:33248 [mailbox.py:close():115] Closing mailbox, abandoning 1 handles.
2025-03-05 15:36:13,684 INFO    Thread-493 (_run_job):33248 [wandb_run.py:_footer_history_summary_info():3958] rendering history
2025-03-05 15:36:13,684 INFO    Thread-493 (_run_job):33248 [wandb_run.py:_footer_history_summary_info():3990] rendering summary
2025-03-05 15:36:13,691 INFO    Thread-493 (_run_job):33248 [wandb_run.py:_footer_sync_info():3919] logging synced files
